Workbook

Sheet Ledger
B1: Customer Name | C1: PNR | D1: Airline | E1: Departure Date | F1: Return Date | G1: Booking Deadline | H1: D. Time | I1: Paid? (X) | J1: Issued date | K1: Type | L1: Fare Cost | M1: Sale Cost | N1: Contact Number (W or T) | O1: Total Pax | P1: profit | Q1: Month | R1: AGENT | S1: Column1
B2: IQBAL/JAVED MR | C2: JADHUY | D2: BA | E2: 45670 | F2: 45709 | I2: X | J2: 45660 | K2: TK | L2: 903.02 | M2: 975 | N2: +44 7466 264988 | O2: 1 | P2: =Table2[[#This Row],[Sale Cost]]-Table2[[#This Row],[Fare Cost]] -> 71.98 | Q2: =MONTH(Table2[[#This Row],[Issued date]]) -> 1
B3: HUSSAIN/SYED TABIB MR | C3: FLODBF | D3: QR | E3: 45662 | F3: 45702 | I3: X | J3: 45660 | K3: TK | L3: 922.82 | M3: 995 | O3: 0 | P3: =Table2[[#This Row],[Sale Cost]]-Table2[[#This Row],[Fare Cost]] -> 72.18 | Q3: =MONTH(Table2[[#This Row],[Issued date]]) -> 1 | T3: Go to Bottom
B4: HUSSAIN/MUZHAIR MR | C4: FXGXFZ | D4: EY | E4: 45675 | F4: 45694 | I4: X | J4: 45661 | K4: TK | L4: 542.32 | M4: 595 | O4: 1 | P4: =Table2[[#This Row],[Sale Cost]]-Table2[[#This Row],[Fare Cost]] -> 52.68 | Q4: =MONTH(Table2[[#This Row],[Issued date]]) -> 1
B5: HAFIZ/FOZIA MRS | C5: LTCFAZ | D5: SV | E5: 45746 | F5: 45770 | I5: X | J5: 45664 | K5: TK | L5: 2683.08 | M5: 3355 | N5: +44 7402 049837 | O5: 4 | P5: =Table2[[#This Row],[Sale Cost]]-Table2[[#This Row],[Fare Cost]] -> 671.92 | Q5: =MONTH(Table2[[#This Row],[Issued date]]) -> 1
B6: KAUR/NIRMAL MRS | C6: JBWKBY | D6: VS | E6: 45680 | F6: 45700 | I6: X | J6: 45667 | K6: TK | L6: 752.32 | M6: 820 | N6: +44 7424 134491 | O6: 1 | P6: =Table2[[#This Row],[Sale Cost]]-Table2[[#This Row],[Fare Cost]] -> 67.68 | Q6: =MONTH(Table2[[#This Row],[Issued date]]) -> 1
B7: IQBAL/MUHAMMAD BILAL MR | C7: QUDZEU | D7: SV | E7: 45667 | F7: 45836 | I7: X | J7: 45667 | K7: TK | L7: 561.77 | M7: 595 | O7: 1 | P7: =Table2[[#This Row],[Sale Cost]]-Table2[[#This Row],[Fare Cost]] -> 33.23 | Q7: =MONTH(Table2[[#This Row],[Issued date]]) -> 1
B8: KHALID/MUHAMMAD MR | C8: OMXGWM | D8: SV | E8: 45669 | F8: 45717 | I8: X | J8: 45667 | K8: TK | L8: 763.42 | M8: 865 | N8: +44 7525 344280 | O8: 1 | P8: =Table2[[#This Row],[Sale Cost]]-Table2[[#This Row],[Fare Cost]] -> 101.58 | Q8: =MONTH(Table2[[#This Row],[Issued date]]) -> 1
B9: BUKHARI/SYEDA MAHRUKH FATIMA MRS | C9: FFGTWW | D9: KU | E9: 45681 | F9: 45754 | I9: X | J9: 45669 | K9: DC | L9: 1244.04 | M9: 1152 | O9: 0 | P9: =Table2[[#This Row],[Sale Cost]]-Table2[[#This Row],[Fare Cost]] -> -92.04 | Q9: =MONTH(Table2[[#This Row],[Issued date]]) -> 1
B10: MEHMOOD/WAJID MR | C10: CUANOK | D10: BA | E10: 45678 | F10: 45696 | I10: X | J10: 45673 | K10: TK | L10: 897.87 | M10: 975 | N10: +44 7828 154128 | O10: 1 | P10: =Table2[[#This Row],[Sale Cost]]-Table2[[#This Row],[Fare Cost]] -> 77.13 | Q10: =MONTH(Table2[[#This Row],[Issued date]]) -> 1
B11: SHAHZAD/KHURAM MR | C11: NHJOIH | D11: QR | E11: 45676 | I11: X | J11: 45674 | K11: TK | L11: 529.33 | M11: 595 | N11: +44 7983 589716 | O11: 1 | P11: =Table2[[#This Row],[Sale Cost]]-Table2[[#This Row],[Fare Cost]] -> 65.67 | Q11: =MONTH(Table2[[#This Row],[Issued date]]) -> 1
B12: ZAINAB/MALEEKA MS | C12: AUNTIN | D12: QR | E12: 45746 | F12: 45772 | I12: X | J12: 45674 | K12: TK | L12: 4627.1 | M12: 4975 | N12: +44 7983 589716 | O12: 5 | P12: =Table2[[#This Row],[Sale Cost]]-Table2[[#This Row],[Fare Cost]] -> 347.9 | Q12: =MONTH(Table2[[#This Row],[Issued date]]) -> 1
B13: KARIM DARR/MOHAMMAD MR*YTH | C13: GGLRFD | D13: BA | E13: 45678 | F13: 45696 | I13: X | J13: 45674 | K13: TK | L13: 809.67 | M13: 935 | N13: +44 7828 154128 | O13: 1 | P13: =Table2[[#This Row],[Sale Cost]]-Table2[[#This Row],[Fare Cost]] -> 125.33 | Q13: =MONTH(Table2[[#This Row],[Issued date]]) -> 1
B14: SULEMAN/GUL NAWAZ MR | C14: JMWMPK | D14: KU | E14: 45858 | F14: 45887 | I14: X | J14: 45675 | K14: TK | L14: 938.82 | M14: 995 | N14: +44 7308 514729 | O14: 1 | P14: =Table2[[#This Row],[Sale Cost]]-Table2[[#This Row],[Fare Cost]] -> 56.18 | Q14: =MONTH(Table2[[#This Row],[Issued date]]) -> 1
B15: SHABIR/MUHAMMAD MR | C15: UUQHWB | D15: EK | E15: 45687 | F15: 45719 | I15: X | J15: 45675 | K15: TK | L15: 745.61 | M15: 815 | N15: +44 7400 631116 | O15: 1 | P15: =Table2[[#This Row],[Sale Cost]]-Table2[[#This Row],[Fare Cost]] -> 69.39 | Q15: =MONTH(Table2[[#This Row],[Issued date]]) -> 1
B16: KAUSAR/MARIA MRS | C16: CYMOBM | D16: BA | E16: 45682 | I16: X | J16: 45676 | K16: TK | L16: 636.5 | M16: 695 | N16: +44 7432 703490 | O16: 1 | P16: =Table2[[#This Row],[Sale Cost]]-Table2[[#This Row],[Fare Cost]] -> 58.5 | Q16: =MONTH(Table2[[#This Row],[Issued date]]) -> 1
B17: SHAH/SYED WASEEM HAIDER MR | C17: ABAPIE | D17: QR | E17: 45721 | F17: 45772 | I17: X | J17: 45677 | K17: TK | L17: 1544.04 | M17: 1690 | N17: +44 7983 589716 | O17: 2 | P17: =Table2[[#This Row],[Sale Cost]]-Table2[[#This Row],[Fare Cost]] -> 145.96 | Q17: =MONTH(Table2[[#This Row],[Issued date]]) -> 1
B18: BEGUM/KHATIJA MRS | C18: HKUNKP | D18: EK | E18: 45683 | F18: 45715 | I18: X | J18: 45677 | K18: TK | L18: 553.61 | M18: 615 | N18: +44 7486 318633 | O18: 1 | P18: =Table2[[#This Row],[Sale Cost]]-Table2[[#This Row],[Fare Cost]] -> 61.39 | Q18: =MONTH(Table2[[#This Row],[Issued date]]) -> 1
B19: Waheed/Abdul Mr | C19: GHEVCT | D19: KU | E19: 45746 | F19: 45791 | I19: X | J19: 45681 | K19: TK | L19: 831.52 | M19: 795 | N19: +44 7404 664682 | O19: 0 | P19: =Table2[[#This Row],[Sale Cost]]-Table2[[#This Row],[Fare Cost]] -> -36.52 | Q19: =MONTH(Table2[[#This Row],[Issued date]]) -> 1
B20: HUSSAIN/HAMZA MR | C20: USGXTM | D20: QR | E20: 45682 | F20: 45757 | I20: X | J20: 45681 | K20: TK | L20: 863.22 | M20: 1095 | O20: 0 | P20: =Table2[[#This Row],[Sale Cost]]-Table2[[#This Row],[Fare Cost]] -> 231.78 | Q20: =MONTH(Table2[[#This Row],[Issued date]]) -> 1
B21: ABBAS/HAIDER MR | C21: JQGRTA | D21: KU | E21: 45837 | F21: 45896 | I21: X | J21: 45684 | K21: TK | L21: 2162.26 | M21: 2465 | O21: 3 | P21: =Table2[[#This Row],[Sale Cost]]-Table2[[#This Row],[Fare Cost]] -> 302.74 | Q21: =MONTH(Table2[[#This Row],[Issued date]]) -> 1
B22: HUSSAIN/KHADIM MR | C22: ONGVBY | D22: BA | E22: 45698 | F22: 45753 | I22: X | J22: 45688 | K22: TK | L22: 908.17 | M22: 995 | N22: +44 7725 084824 | O22: 1 | P22: =Table2[[#This Row],[Sale Cost]]-Table2[[#This Row],[Fare Cost]] -> 86.83 | Q22: =MONTH(Table2[[#This Row],[Issued date]]) -> 1
B23: ADREES/HAFIZ MUHAMMAD MR | C23: EOHNKX | D23: EK/FZ | E23: 45692 | I23: X | J23: 45690 | K23: TK | L23: 405.9 | M23: 455 | N23: +44 7951 770730 | O23: 2 | P23: =Table2[[#This Row],[Sale Cost]]-Table2[[#This Row],[Fare Cost]] -> 49.1 | Q23: =MONTH(Table2[[#This Row],[Issued date]]) -> 2
B24: HUSSAIN/KHALID MR | C24: HLAYZW | D24: GF | E24: 45691 | F24: 45723 | I24: X | J24: 45691 | K24: TK | L24: 2042.92 | M24: 2400 | N24: +44 7754 356742 | O24: 2 | P24: =Table2[[#This Row],[Sale Cost]]-Table2[[#This Row],[Fare Cost]] -> 357.08 | Q24: =MONTH(Table2[[#This Row],[Issued date]]) -> 2
B25: ALI/HUSAIN MR | C25: NHRGDA | D25: BA | E25: 45697 | F25: 45724 | I25: X | J25: 45694 | K25: TK | L25: 749.87 | M25: 845 | N25: +44 7304 072807 | O25: 1 | P25: =Table2[[#This Row],[Sale Cost]]-Table2[[#This Row],[Fare Cost]] -> 95.13 | Q25: =MONTH(Table2[[#This Row],[Issued date]]) -> 2
B26: BI/SAIMA MRS | C26: IQEGJG | D26: BA | E26: 45770 | F26: 45804 | I26: X | J26: 45711 | K26: TK | L26: 700.27 | M26: 775 | N26: +44 7904 251399 | O26: 1 | P26: =Table2[[#This Row],[Sale Cost]]-Table2[[#This Row],[Fare Cost]] -> 74.73 | Q26: =MONTH(Table2[[#This Row],[Issued date]]) -> 2
B27: RAJA/MOHAMMAD NAEEM MR | C27: GILLNC | D27: QR | E27: 45706 | F27: 45730 | I27: X | J27: 45696 | K27: TK | L27: 643.82 | M27: 695 | N27: +44 7454 868818 | O27: 2 | P27: =Table2[[#This Row],[Sale Cost]]-Table2[[#This Row],[Fare Cost]] -> 51.18 | Q27: =MONTH(Table2[[#This Row],[Issued date]]) -> 2
B28: BI/ASHIA MRS | C28: OCBBZL | D28: QR | E28: 45707 | F28: 45743 | I28: X | J28: 45705 | K28: TK | L28: 643.52 | M28: 725 | N28: +44 7400 050602 | O28: 1 | P28: =Table2[[#This Row],[Sale Cost]]-Table2[[#This Row],[Fare Cost]] -> 81.48 | Q28: =MONTH(Table2[[#This Row],[Issued date]]) -> 2
B29: RIAZ/AZMAT MR | C29: WNKDNO | D29: QR | E29: 45742 | F29: 45755 | I29: X | J29: 45705 | K29: TK | L29: 1000.52 | M29: 1095 | N29: +44 7979 612000 | O29: 1 | P29: =Table2[[#This Row],[Sale Cost]]-Table2[[#This Row],[Fare Cost]] -> 94.48 | Q29: =MONTH(Table2[[#This Row],[Issued date]]) -> 2
B30: NAYER/SYED KAMRAN MR | C30: AVCZBY | D30: KU | E30: 45667 | F30: 45714 | I30: X | J30: 45706 | K30: DC | L30: 20 | M30: 175 | N30: +44 7387 294198 | O30: 1 | P30: =Table2[[#This Row],[Sale Cost]]-Table2[[#This Row],[Fare Cost]] -> 155 | Q30: =MONTH(Table2[[#This Row],[Issued date]]) -> 2
B31: KHAN/ISHTIAQ AHMED MR | C31: JUPIQC | D31: EY | E31: 45711 | F31: 45733 | I31: X | J31: 45706 | K31: TK | L31: 525.22 | M31: 595 | N31: +44 7828 860470 | O31: 0 | P31: =Table2[[#This Row],[Sale Cost]]-Table2[[#This Row],[Fare Cost]] -> 69.78 | Q31: =MONTH(Table2[[#This Row],[Issued date]]) -> 2
B32: KHAN/NOOR MR | C32: KHEMHB | D32: EY | E32: 45727 | F32: 45799 | I32: X | J32: 45707 | K32: TK | L32: 525.12 | M32: 595 | N32: +44 7828 860470 | O32: 2 | P32: =Table2[[#This Row],[Sale Cost]]-Table2[[#This Row],[Fare Cost]] -> 69.88 | Q32: =MONTH(Table2[[#This Row],[Issued date]]) -> 2
B33: RAMZAN/IFRA MRS | C33: JRYFXX | D33: BA | E33: 45739 | F33: 45770 | I33: X | J33: 45709 | K33: TK | L33: 2281.64 | M33: 2430 | N33: +44 7393 748601 | O33: 2 | P33: =Table2[[#This Row],[Sale Cost]]-Table2[[#This Row],[Fare Cost]] -> 148.36 | Q33: =MONTH(Table2[[#This Row],[Issued date]]) -> 2
B34: PARVEZ/MUHAMMAD MR | C34: SSNWDS | D34: EK | E34: 45854 | F34: 45894 | I34: Installements | J34: 45710 | K34: TK | L34: 4260 | M34: 4460 | N34: +44 7922 710949 | O34: 4 | P34: =Table2[[#This Row],[Sale Cost]]-Table2[[#This Row],[Fare Cost]] -> 200 | Q34: =MONTH(Table2[[#This Row],[Issued date]]) -> 2
B35: MEHARBAN/MOHAMMED MR | C35: JZAQMY | D35: QR | E35: 45735 | F35: 45748 | I35: X | J35: 45714 | K35: TK | L35: 793.22 | M35: 865 | N35: +44 7459 380433 | O35: 1 | P35: =Table2[[#This Row],[Sale Cost]]-Table2[[#This Row],[Fare Cost]] -> 71.78 | Q35: =MONTH(Table2[[#This Row],[Issued date]]) -> 2
B36: MOHAMANDI/OBAIDULLAH MR | C36: WGXLQE | D36: PK/SV | E36: 45762 | F36: 45772 | I36: X | J36: 45714 | K36: TK | L36: 1555 | N36: +44 7400 741723 | O36: 0 | P36: =Table2[[#This Row],[Sale Cost]]-Table2[[#This Row],[Fare Cost]] -> -1555 | Q36: =MONTH(Table2[[#This Row],[Issued date]]) -> 2
B37: MOHAMANDI/OBAIDULLAH MR | C37: UXQKCU | D37: QR | E37: 45723 | I37: X | J37: 45715 | K37: TK | L37: 727.84 | N37: +44 7400 741723 | O37: 0 | P37: =Table2[[#This Row],[Sale Cost]]-Table2[[#This Row],[Fare Cost]] -> -727.84 | Q37: =MONTH(Table2[[#This Row],[Issued date]]) -> 2
B38: AHMED/AYESHA KHAN MRS | C38: SQQNDB | D38: BA | E38: 45748 | F38: 45806 | I38: X | J38: 45716 | K38: TK | L38: 921.12 | M38: 995 | N38: +44 7570 549352 | O38: 0 | P38: =Table2[[#This Row],[Sale Cost]]-Table2[[#This Row],[Fare Cost]] -> 73.88 | Q38: =MONTH(Table2[[#This Row],[Issued date]]) -> 2
B39: AHMED/IFTIKHAR MR | C39: QBZTWF | D39: BA | E39: 45788 | F39: 45806 | I39: X | J39: 45716 | K39: TK | L39: 637.12 | M39: 695 | N39: +44 7570 549352 | O39: 0 | P39: =Table2[[#This Row],[Sale Cost]]-Table2[[#This Row],[Fare Cost]] -> 57.88 | Q39: =MONTH(Table2[[#This Row],[Issued date]]) -> 2
B40: HUSSAIN/SAJID MR | C40: LPLBFW | D40: BA | E40: 45727 | F40: 45751 | I40: X | J40: 45717 | K40: TK | L40: 1855.91 | M40: 1856 | O40: 0 | P40: =Table2[[#This Row],[Sale Cost]]-Table2[[#This Row],[Fare Cost]] -> 0.09 | Q40: =MONTH(Table2[[#This Row],[Issued date]]) -> 3
...

Sheet Umrah
A1: Issue Date | B1: Customer Name | C1: PNR | D1: Departure Date | E1: Return Date | F1: Ticket (£) | G1: Hotel (£) | H1: Transport (£) | I1: Visa (£) | J1: Net Cost | K1: Payment Date | L1: Sale cost | M1: Paid? (X) | N1: Profit | O1: Notes | P1: Com | Q1: Month
A2: 45658 | F2: 0 | G2: 0 | H2: 0 | I2: 0 | J2: =SUM(Table3[[#This Row],[Ticket (£)]:[Visa (£)]]) -> 0 | L2: 0 | N2: =L2-J2 -> 0 | P2: =N2*10% -> 0 | Q2: =MONTH(Table3[[#This Row],[Issue Date]]) -> 1
A3: 45839 | B3: Sajid Hussain | C3: FQKGNI | D3: 45933 | E3: 45940 | F3: 2398.1 | G3: =484.42+256.99 -> 741.41 | H3: 221 | I3: 225 | J3: =SUM(Table3[[#This Row],[Ticket (£)]:[Visa (£)]]) -> 3585.51 | K3: =DATE(2025,7,1) -> 45839 | L3: 4425 | M3: X | N3: =L3-J3 -> 839.49 | O3: Issued by Hussaini | P3: =N3*10% -> 83.949 | Q3: =MONTH(Table3[[#This Row],[Issue Date]]) -> 7
A4: 45870 | B4: Abdul Wahid | C4: UYNJRK, FJUTUV, MDKBWA | D4: 27/09/2025, 05/10/2025 | E4: 21/10/2025, 26/11/2025 | F4: =(720*4)+(800*2)+81.92 -> 4561.92 | G4: =2002.31 -> 2002.31 | H4: 278 | I4: =65*6 -> 390 | J4: =SUM(Table3[[#This Row],[Ticket (£)]:[Visa (£)]]) -> 7232.23 | K4: 45870 | L4: 7670 | M4: X | N4: =L4-J4 -> 437.77 | O4: £81.92 loss by ticket fare issuance, Saudi Tickets issued by Rida, Rest issued by Hussaini | P4: 0 | Q4: =MONTH(Table3[[#This Row],[Issue Date]]) -> 8
A5: 45871 | B5: Muhammad Hanif | C5: UYSMOE, QROVMG | D5: 27/09/2025, 05/10/2025 | E5: 46153 | F5: =535.82+146.2 -> 682.02 | G5: =312.62+346.57 -> 659.19 | H5: 0 | I5: 65 | J5: =SUM(Table3[[#This Row],[Ticket (£)]:[Visa (£)]]) -> 1406.21 | L5: 1635 | M5: X | N5: =L5-J5 -> 228.79 | O5: Tickets x1 £5 | P5: 0 | Q5: =MONTH(Table3[[#This Row],[Issue Date]]) -> 8
A6: 45874 | B6: Syed Ali Nasir | C6: SHQMOO | D6: 45951 | E6: 45961 | F6: =SUM((457.56*4)+(367.56*2)) -> 2565.36 | G6: =898.59+690.38 -> 1588.97 | H6: 278 | I6: =65*6 -> 390 | J6: =SUM(Table3[[#This Row],[Ticket (£)]:[Visa (£)]]) -> 4822.33 | K6: 45905 | L6: 5100 | N6: =L6-J6 -> 277.67 | O6: Tickets x6 £5 | P6: 0 | Q6: =MONTH(Table3[[#This Row],[Issue Date]]) -> 8
A7: 45876 | B7: Syed Nasir Ali Shah | C7: ASTFDI | D7: 10/10/2025, 16/10/2025 | E7: 16/10/2025, 15/11/2025 | F7: =SUM((118.8*4)+(139.8*2)+(385.42*4)+(522.42*2)) -> 3341.32 | G7: =460.53+1009.26-111.02 -> 1358.77 | H7: 278 | I7: =(65*5)+200 -> 525 | J7: =SUM(Table3[[#This Row],[Ticket (£)]:[Visa (£)]]) -> 5503.09 | K7: 45876 | L7: 5900 | N7: =L7-J7 -> 396.91 | O7: Tickets x6 £5 | P7: 0 | Q7: =MONTH(Table3[[#This Row],[Issue Date]]) -> 8
A8: 45883 | B8: Michael Tichaona Manyangadze | C8: W95342 | D8: 45884 | E8: 45919 | F8: =431.63+507.96 -> 939.59 | G8: =1517.3-284.18 -> 1233.12 | H8: =69.19-6.23 -> 62.96 | I8: 0 | J8: =SUM(Table3[[#This Row],[Ticket (£)]:[Visa (£)]]) -> 2235.67 | K8: 45883 | L8: 2750 | N8: =L8-J8 -> 514.33 | O8: N/A | P8: 0 | Q8: =MONTH(Table3[[#This Row],[Issue Date]]) -> 8
A9: 45879 | B9: Naveed Abbas | C9: W95327 | D9: 45911 | E9: 45916 | F9: =408.26 -> 408.26 | G9: =456.95-50.26 -> 406.69 | H9: =70-6.3 -> 63.7 | I9: 100.76 | J9: =SUM(Table3[[#This Row],[Ticket (£)]:[Visa (£)]]) -> 979.41 | K9: 45879 | L9: 1240 | N9: =L9-J9 -> 260.59 | O9: N/A | P9: 0 | Q9: =MONTH(Table3[[#This Row],[Issue Date]]) -> 8
A10: 45884 | B10: Rashdaw Anwar | F10: 2276.52 | G10: 0 | H10: 76 | I10: 160 | J10: =SUM(Table3[[#This Row],[Ticket (£)]:[Visa (£)]]) -> 2512.52 | K10: 45885 | L10: 3000 | N10: =L10-J10 -> 487.48 | O10: Tickets x6 £5 | P10: 0 | Q10: =MONTH(Table3[[#This Row],[Issue Date]]) -> 8
A11: 45887 | B11: Shazia Khalid | F11: 0 | G11: =661.56+322.19-31.5-15.34 -> 936.91 | H11: 325 | I11: =276+155 -> 431 | J11: =SUM(Table3[[#This Row],[Ticket (£)]:[Visa (£)]]) -> 1692.91 | L11: 1915 | N11: 0 | O11: N/A | P11: =N11*10% -> 0 | Q11: =MONTH(Table3[[#This Row],[Issue Date]]) -> 8
A12: 45890 | B12: Misom Zaidi | F12: 0 | G12: =60.76+53.03 -> 113.79 | H12: 0 | I12: 0 | J12: =SUM(Table3[[#This Row],[Ticket (£)]:[Visa (£)]]) -> 113.79 | L12: 0 | N12: =L12-J12 -> -113.79 | O12: N/A | P12: 0 | Q12: =MONTH(Table3[[#This Row],[Issue Date]]) -> 8
A13: 45892 | B13: Sakhawat Hussain | F13: =824.94+821.13 -> 1646.07 | G13: =395.3+169.59 -> 564.89 | H13: 300 | I13: 483.54 | J13: =SUM(Table3[[#This Row],[Ticket (£)]:[Visa (£)]]) -> 2994.5 | L13: 3000 | N13: =L13-J13 -> 5.5 | O13: N/A | P13: 0 | Q13: =MONTH(Table3[[#This Row],[Issue Date]]) -> 8
F14: 0 | G14: 0 | H14: 0 | I14: 0 | J14: =SUM(Table3[[#This Row],[Ticket (£)]:[Visa (£)]]) -> 0 | L14: 0 | N14: =L14-J14 -> 0 | P14: =N14*10% -> 0 | Q14: =MONTH(Table3[[#This Row],[Issue Date]]) -> 1
F15: 0 | G15: 0 | H15: 0 | I15: 0 | J15: =SUM(Table3[[#This Row],[Ticket (£)]:[Visa (£)]]) -> 0 | L15: 0 | N15: =L15-J15 -> 0 | P15: =N15*10% -> 0 | Q15: =MONTH(Table3[[#This Row],[Issue Date]]) -> 1
F16: 0 | G16: 0 | H16: 0 | I16: 0 | J16: =SUM(Table3[[#This Row],[Ticket (£)]:[Visa (£)]]) -> 0 | L16: 0 | N16: =L16-J16 -> 0 | P16: =N16*10% -> 0 | Q16: =MONTH(Table3[[#This Row],[Issue Date]]) -> 1
F17: 0 | G17: 0 | H17: 0 | I17: 0 | J17: =SUM(Table3[[#This Row],[Ticket (£)]:[Visa (£)]]) -> 0 | L17: 0 | N17: =L17-J17 -> 0 | P17: =N17*10% -> 0 | Q17: =MONTH(Table3[[#This Row],[Issue Date]]) -> 1
A18: 45689 | F18: 0 | G18: 0 | H18: 0 | I18: 0 | J18: =SUM(Table3[[#This Row],[Ticket (£)]:[Visa (£)]]) -> 0 | L18: 0 | N18: =L18-J18 -> 0 | P18: =N18*10% -> 0 | Q18: =MONTH(Table3[[#This Row],[Issue Date]]) -> 2
A19: 45717 | F19: 0 | G19: 0 | H19: 0 | I19: 0 | J19: =SUM(Table3[[#This Row],[Ticket (£)]:[Visa (£)]]) -> 0 | L19: 0 | N19: =L19-J19 -> 0 | P19: =N19*10% -> 0 | Q19: =MONTH(Table3[[#This Row],[Issue Date]]) -> 3
A20: 45748 | F20: 0 | G20: 0 | H20: 0 | I20: 0 | J20: =SUM(Table3[[#This Row],[Ticket (£)]:[Visa (£)]]) -> 0 | L20: 0 | N20: =L20-J20 -> 0 | P20: =N20*10% -> 0 | Q20: =MONTH(Table3[[#This Row],[Issue Date]]) -> 4
A21: 45778 | F21: 0 | G21: 0 | H21: 0 | I21: 0 | J21: =SUM(Table3[[#This Row],[Ticket (£)]:[Visa (£)]]) -> 0 | L21: 0 | N21: =L21-J21 -> 0 | P21: =N21*10% -> 0 | Q21: =MONTH(Table3[[#This Row],[Issue Date]]) -> 5
A22: 45809 | F22: 0 | G22: 0 | H22: 0 | I22: 0 | J22: =SUM(Table3[[#This Row],[Ticket (£)]:[Visa (£)]]) -> 0 | L22: 0 | N22: =L22-J22 -> 0 | P22: =N22*10% -> 0 | Q22: =MONTH(Table3[[#This Row],[Issue Date]]) -> 6
A23: 45870 | F23: 0 | G23: 0 | H23: 0 | I23: 0 | J23: =SUM(Table3[[#This Row],[Ticket (£)]:[Visa (£)]]) -> 0 | L23: 0 | N23: =L23-J23 -> 0 | P23: =N23*10% -> 0 | Q23: =MONTH(Table3[[#This Row],[Issue Date]]) -> 8
A24: 45901 | F24: 0 | G24: 0 | H24: 0 | I24: 0 | J24: =SUM(Table3[[#This Row],[Ticket (£)]:[Visa (£)]]) -> 0 | L24: 0 | N24: =L24-J24 -> 0 | P24: =N24*10% -> 0 | Q24: =MONTH(Table3[[#This Row],[Issue Date]]) -> 9
A25: 45931 | F25: 0 | G25: 0 | H25: 0 | I25: 0 | J25: =SUM(Table3[[#This Row],[Ticket (£)]:[Visa (£)]]) -> 0 | L25: 0 | N25: =L25-J25 -> 0 | P25: =N25*10% -> 0 | Q25: =MONTH(Table3[[#This Row],[Issue Date]]) -> 10
A26: 45962 | F26: 0 | G26: 0 | H26: 0 | I26: 0 | J26: =SUM(Table3[[#This Row],[Ticket (£)]:[Visa (£)]]) -> 0 | L26: 0 | N26: =L26-J26 -> 0 | P26: =N26*10% -> 0 | Q26: =MONTH(Table3[[#This Row],[Issue Date]]) -> 11
A27: 45992 | B27: placeholder | F27: 0 | G27: 0 | H27: 0 | I27: 0 | J27: =SUM(Table3[[#This Row],[Ticket (£)]:[Visa (£)]]) -> 0 | L27: 0 | N27: =L27-J27 -> 0 | P27: =N27*10% -> 0 | Q27: =MONTH(Table3[[#This Row],[Issue Date]]) -> 12
N28: =SUM(Table3[Profit]) -> 3334.74 | P28: =SUM(P4:P27) -> 0

Sheet Low Fare
B1: PNR | C1: Original Fare | D1: New Lower Fare | E1: Difference | F1: Date | G1: 10% | H1: Month
B2: ABAPIE | C2: 772.02 | D2: 736.02 | E2: =Changes[[#This Row],[Original Fare]]-Changes[[#This Row],[New Lower Fare]] -> 36 | F2: 45677 | G2: =Changes[[#This Row],[Difference]]*10% -> 3.6 | H2: =MONTH(Changes[[#This Row],[Date]]) -> 1
B3: ABAPIE | C3: 772.02 | D3: 736.02 | E3: =Changes[[#This Row],[Original Fare]]-Changes[[#This Row],[New Lower Fare]] -> 36 | F3: 45677 | G3: =Changes[[#This Row],[Difference]]*10% -> 3.6 | H3: =MONTH(Changes[[#This Row],[Date]]) -> 1
B4: AYUVFW | C4: 934.92 | D4: 893.42 | E4: =Changes[[#This Row],[Original Fare]]-Changes[[#This Row],[New Lower Fare]] -> 41.5 | F4: 45747 | G4: =Changes[[#This Row],[Difference]]*10% -> 4.15 | H4: =MONTH(Changes[[#This Row],[Date]]) -> 3
B5: JUHMCT | C5: 643.22 | D5: 587.82 | E5: =Changes[[#This Row],[Original Fare]]-Changes[[#This Row],[New Lower Fare]] -> 55.4 | F5: 45756 | G5: =Changes[[#This Row],[Difference]]*10% -> 5.54 | H5: =MONTH(Changes[[#This Row],[Date]]) -> 4
B6: JEYVQB | C6: 1112.52 | D6: 1042.52 | E6: =Changes[[#This Row],[Original Fare]]-Changes[[#This Row],[New Lower Fare]] -> 70 | F6: 45800 | G6: =Changes[[#This Row],[Difference]]*10% -> 7 | H6: =MONTH(Changes[[#This Row],[Date]]) -> 5
B7: NZYGDJ | C7: 1238.82 | D7: 1192.52 | E7: =Changes[[#This Row],[Original Fare]]-Changes[[#This Row],[New Lower Fare]] -> 46.3 | F7: 45854 | G7: =Changes[[#This Row],[Difference]]*50% -> 23.15 | H7: =MONTH(Changes[[#This Row],[Date]]) -> 7 | I7: 50% from June
B8: SAEBXO | C8: 1147.42 | D8: 1100.42 | E8: =Changes[[#This Row],[Original Fare]]-Changes[[#This Row],[New Lower Fare]] -> 47 | F8: 45876 | G8: =Changes[[#This Row],[Difference]]*50% -> 23.5 | H8: =MONTH(Changes[[#This Row],[Date]]) -> 8
B9: SAEBXO | C9: 1147.42 | D9: 1100.42 | E9: =Changes[[#This Row],[Original Fare]]-Changes[[#This Row],[New Lower Fare]] -> 47 | F9: 45876 | G9: =Changes[[#This Row],[Difference]]*50% -> 23.5 | H9: =MONTH(Changes[[#This Row],[Date]]) -> 8
B10: SAEBXO | C10: 1147.42 | D10: 1100.42 | E10: =Changes[[#This Row],[Original Fare]]-Changes[[#This Row],[New Lower Fare]] -> 47 | F10: 45876 | G10: =Changes[[#This Row],[Difference]]*50% -> 23.5 | H10: =MONTH(Changes[[#This Row],[Date]]) -> 8
B11: GMIUMK | C11: 703.88 | D11: 583.88 | E11: =Changes[[#This Row],[Original Fare]]-Changes[[#This Row],[New Lower Fare]] -> 120 | F11: 45897 | G11: =Changes[[#This Row],[Difference]]*50% -> 60 | H11: =MONTH(Changes[[#This Row],[Date]]) -> 8
B12: ITZJAH | C12: 609.62 | D12: 547.22 | E12: =Changes[[#This Row],[Original Fare]]-Changes[[#This Row],[New Lower Fare]] -> 62.4 | F12: 45908 | G12: =Changes[[#This Row],[Difference]]*50% -> 31.2 | H12: =MONTH(Changes[[#This Row],[Date]]) -> 9
B13: CDVHFS | C13: 559.22 | D13: 477.22 | E13: =Changes[[#This Row],[Original Fare]]-Changes[[#This Row],[New Lower Fare]] -> 82 | F13: 45908 | G13: =Changes[[#This Row],[Difference]]*50% -> 41 | H13: =MONTH(Changes[[#This Row],[Date]]) -> 9
B14: CDVHFS | C14: 559.22 | D14: 477.22 | E14: =Changes[[#This Row],[Original Fare]]-Changes[[#This Row],[New Lower Fare]] -> 82 | F14: 45908 | G14: =Changes[[#This Row],[Difference]]*50% -> 41 | H14: =MONTH(Changes[[#This Row],[Date]]) -> 9
B15: KFNZAK | C15: 585.32 | D15: 524.92 | E15: =Changes[[#This Row],[Original Fare]]-Changes[[#This Row],[New Lower Fare]] -> 60.4 | F15: 45913 | G15: =Changes[[#This Row],[Difference]]*50% -> 30.2 | H15: =MONTH(Changes[[#This Row],[Date]]) -> 9
B16: FYTKDR | C16: 1383.08 | D16: 1154.08 | E16: =Changes[[#This Row],[Original Fare]]-Changes[[#This Row],[New Lower Fare]] -> 229 | F16: 45933 | G16: =Changes[[#This Row],[Difference]]*50% -> 114.5 | H16: =MONTH(Changes[[#This Row],[Date]]) -> 10
B17: AJCQXC | C17: 668 | D17: 548 | E17: =Changes[[#This Row],[Original Fare]]-Changes[[#This Row],[New Lower Fare]] -> 120 | F17: 45957 | G17: =Changes[[#This Row],[Difference]]*50% -> 60 | H17: =MONTH(Changes[[#This Row],[Date]]) -> 10
B18: DKPKUS | C18: 650.02 | D18: 630.12 | E18: =Changes[[#This Row],[Original Fare]]-Changes[[#This Row],[New Lower Fare]] -> 19.9 | F18: 45957 | G18: =Changes[[#This Row],[Difference]]*50% -> 9.95 | H18: =MONTH(Changes[[#This Row],[Date]]) -> 10
B19: DKPKUS | C19: 650.02 | D19: 630.12 | E19: =Changes[[#This Row],[Original Fare]]-Changes[[#This Row],[New Lower Fare]] -> 19.9 | F19: 45957 | G19: =Changes[[#This Row],[Difference]]*50% -> 9.95 | H19: =MONTH(Changes[[#This Row],[Date]]) -> 10
... B25: JEYUIN | C25: 960.62 | D25: 945.12 | E25: =Changes[[#This Row],[Original Fare]]-Changes[[#This Row],[New Lower Fare]] -> 15.5 | F25: 45967 | G25: =Changes[[#This Row],[Difference]]*50% -> 7.75 | H25: =MONTH(Changes[[#This Row],[Date]]) -> 11
B26: UQBYKT | C26: 1300.77 | D26: 1218.37 | E26: =Changes[[#This Row],[Original Fare]]-Changes[[#This Row],[New Lower Fare]] -> 82.4 | F26: 45973 | G26: =Changes[[#This Row],[Difference]]*50% -> 41.2
B27: UQBYKT | C27: 1300.77 | D27: 1218.37 | E27: =Changes[[#This Row],[Original Fare]]-Changes[[#This Row],[New Lower Fare]] -> 82.4 | F27: 45973 | G27: =Changes[[#This Row],[Difference]]*50% -> 41.2
B28: UQBYKT | C28: 1300.77 | D28: 1218.37 | E28: =Changes[[#This Row],[Original Fare]]-Changes[[#This Row],[New Lower Fare]] -> 82.4 | F28: 45973 | G28: =Changes[[#This Row],[Difference]]*50% -> 41.2
B29: UQBYKT | C29: 1300.77 | D29: 1218.37 | E29: =Changes[[#This Row],[Original Fare]]-Changes[[#This Row],[New Lower Fare]] -> 82.4 | F29: 45973 | G29: =Changes[[#This Row],[Difference]]*50% -> 41.2
B30: IUYRBH | C30: 1573.77 | D30: 1289.78 | E30: =Changes[[#This Row],[Original Fare]]-Changes[[#This Row],[New Lower Fare]] -> 283.99 | F30: 45975 | G30: =Changes[[#This Row],[Difference]]*50% -> 141.995
E31: =Changes[[#This Row],[Original Fare]]-Changes[[#This Row],[New Lower Fare]] -> 0 | G31: =Changes[[#This Row],[Difference]]*50% -> 0
E32: =Changes[[#This Row],[Original Fare]]-Changes[[#This Row],[New Lower Fare]] -> 0 | F32: 45689 | G32: =Changes[[#This Row],[Difference]]*50% -> 0 | H32: =MONTH(Changes[[#This Row],[Date]]) -> 2
F33: 45809 | G33: =Changes[[#This Row],[Difference]]*50% -> 0 | H33: =MONTH(Changes[[#This Row],[Date]]) -> 6
E34: =Changes[[#This Row],[Original Fare]]-Changes[[#This Row],[New Lower Fare]] -> 0 | F34: 45962 | G34: =Changes[[#This Row],[Difference]]*50% -> 0 | H34: =MONTH(Changes[[#This Row],[Date]]) -> 11
E35: =Changes[[#This Row],[Original Fare]]-Changes[[#This Row],[New Lower Fare]] -> 0 | F35: 45992 | G35: =Changes[[#This Row],[Difference]]*50% -> 0 | H35: =MONTH(Changes[[#This Row],[Date]]) -> 12
B36: Insert new line above | D36: Total Commission | E36: =SUM(E2:E35) -> 1930.39 | G36: =Changes[[#This Row],[Difference]]*10% -> 193.039 | H36: 0.1

Sheet Statistics

Sheet Settings
H1: Ticket Quantity | M1: Low Fare
B2: Month | C2: Count | E2: Month | F2: Sum of profit | H2: Month | I2: Sum of Total Pax | J2: (<=30 = £5 per ticket) | K2: >=31 = £10 per ticket | M2: Month | N2: Sum of 10%
B3: JANUARY | C3: =COUNTIF(Ledger!Q2:Q345,"=1") -> 21 | E3: 1 | F3: 2571.49 | H3: 1 | I3: 27 | J3: =I3*5 -> 135 | K3: N/A | M3: 1 | N3: 7.2
B4: FEBRUARY | C4: =COUNTIF(Ledger!Q2:Q345,"=2") -> 17 | E4: 2 | F4: -633.1 | H4: 2 | I4: 20 | J4: =I4*5 -> 100 | K4: N/A | M4: 2 | N4: 0
B5: MARCH | C5: =COUNTIF(Ledger!Q2:Q345,"=3") -> 16 | E5: 3 | F5: 2129.95 | H5: 3 | I5: 21 | J5: =I5*5 -> 105 | K5: N/A | M5: 3 | N5: 4.15
B6: APRIL | C6: =COUNTIF(Ledger!Q2:Q345,"=4") -> 28 | E6: 4 | F6: 3197.08 | H6: 4 | I6: 23 | J6: =I6*5 -> 115 | K6: N/A | M6: 4 | N6: 5.54
B7: MAY | C7: =COUNTIF(Ledger!Q2:Q345,"=5") -> 17 | E7: 5 | F7: -103.86 | H7: 5 | I7: 15 | J7: =I7*5 -> 75 | K7: N/A | M7: 5 | N7: 7
B8: JUNE | C8: =COUNTIF(Ledger!Q2:Q345,"=6") -> 24 | E8: 6 | F8: 1716.83 | H8: 6 | I8: 40 | J8: =MIN(I8,30)*5 -> 150 | K8: =MAX(I8-30,0)*10 -> 100 | M8: 6 | N8: 0
B9: JULY | C9: =COUNTIF(Ledger!Q2:Q345,"=7") -> 20 | E9: 7 | F9: 404.62 | H9: 7 | I9: 30 | J9: =MIN(I9,30)*5 -> 150 | K9: =MAX(I9-30,0)*10 -> 0 | M9: 7 | N9: 23.15
B10: AUGUST | C10: =COUNTIF(Ledger!Q2:Q345,"=8") -> 27 | E10: 8 | F10: -781 | H10: 8 | I10: 44 | J10: =MIN(I10,30)*5 -> 150 | K10: =MAX(I10-30,0)*10 -> 140 | M10: 8 | N10: 130.5
B11: SEPTEMBER | C11: =COUNTIF(Ledger!Q2:Q345,"=9") -> 28 | E11: 9 | F11: 2021.92 | H11: 9 | I11: 28 | J11: =MIN(I11,30)*5 -> 140 | K11: =MAX(I11-30,0)*10 -> 0 | M11: 9 | N11: 143.4
B12: OCTOBER | C12: =COUNTIF(Ledger!Q2:Q345,"=10") -> 41 | E12: 10 | F12: 6450.88 | H12: 10 | I12: 48 | J12: =MIN(I12,30)*5 -> 150 | K12: =MAX(I12-30,0)*10 -> 180 | M12: 10 | N12: 234.15
B13: NOVEMBER | C13: =COUNTIF(Ledger!Q2:Q345,"=11") -> 7 | E13: 11 | F13: 413.52 | H13: 11 | I13: 10 | J13: =MIN(I13,30)*5 -> 50 | K13: =MAX(I13-30,0)*10 -> 0 | M13: 11 | N13: 0
B14: DECEMBER | C14: =COUNTIF(Ledger!Q2:Q345,"=12") -> 1 | E14: 12 | F14: 0 | H14: 12 | I14: 0 | J14: =MIN(I14,30)*5 -> 0 | K14: =MAX(I14-30,0)*10 -> 0 | M14: 12 | N14: 0
E15: Grand Total | F15: 17388.33 | H15: Grand Total | I15: 306 | J15: =SUM(J3:J14) -> 1320 | K15: =SUM(K3:K14) -> 420 | M15: Grand Total | N15: 555.09
B18: Umrah | E18: Ignore
B19: Month | C19: Sum of Com | E19: Month | F19: Sum of Fare Cost | G19: Sum of Sale Cost | H19: Sum of profit | J19: Month | K19: Total Commission
B20: 1 | C20: 0 | E20: 1 | F20: 24420.51 | G20: 26992 | H20: 2571.49 | J20: January | K20: =SUM(J3,N3,C20) -> 142.2
B21: 2 | C21: 0 | E21: 2 | F21: 18433.1 | G21: 17800 | H21: -633.1 | J21: February | K21: =SUM(J4,N4,C21) -> 100
B22: 3 | C22: 0 | E22: 3 | F22: 20546.05 | G22: 22676 | H22: 2129.95 | J22: March | K22: =SUM(J5,N5,C22) -> 109.15
B23: 4 | C23: 0 | E23: 4 | F23: 32283.81 | G23: 35480.89 | H23: 3197.08 | J23: April | K23: =SUM(J6,N6,C23) -> 120.54
B24: 5 | C24: 0 | E24: 5 | F24: 13748.86 | G24: 13645 | H24: -103.86 | J24: May | K24: =SUM(J7,N7,C24) -> 82
B25: 6 | C25: 0 | E25: 6 | F25: 26633.17 | G25: 28350 | H25: 1716.83 | J25: June | K25: =SUM(J8:K8,N8,C25) -> 250
B26: 7 | C26: 83.949 | E26: 7 | F26: 22300.38 | G26: 22705 | H26: 404.62 | J26: July | K26: =SUM(J9:K9,N9,C26) -> 257.099
B27: 8 | C27: 0 | E27: 8 | F27: 28530 | G27: 27749 | H27: -781 | J27: August | K27: =SUM(J10:K10,N10,C27) -> 420.5
B28: 9 | C28: 0 | E28: 9 | F28: 18363.72 | G28: 20385.64 | H28: 2021.92 | J28: September | K28: =SUM(J11:K11,N11,C28) -> 283.4
B29: 10 | C29: 0 | E29: 10 | F29: 37572.6 | G29: 44023.48 | H29: 6450.88 | J29: October | K29: =SUM(J12:K12,N12,C29) -> 564.15
B30: 11 | C30: 0 | E30: 11 | F30: 3391.48 | G30: 3805 | H30: 413.52 | J30: November | K30: =SUM(J13:K13,N13,C30) -> 50
B31: 12 | C31: 0 | E31: 12 | F31: 0 | G31: 0 | H31: 0 | J31: December | K31: =SUM(J14:K14,N14,C31) -> 0
B32: Grand Total | C32: 83.949 | E32: Grand Total | F32: 246223.68 | G32: 263612.01 | H32: 17388.33 | J32: Total | K32: =SUM(K20:K31) -> 2379.039

Sheet Payments
A1: This record is for yourself and is not monitored
A3: Date | B3: Name | C3: Payment date | D3: Total Amount due | E3: Payment 1 | F3: Payment 2 | G3: Payment 3 | H3: Payment 4 | I3: Payment 5 | J3: Payment 6 | K3: Payment 7 | L3: Payment 8 | M3: Payment 9 | N3: Payment 10 | O3: BALANCE
A4: 45591 | B4: Habib Ullah - 4 installments | C4: 29 of every month | D4: 3325 | E4: 1000 | F4: 581.25 | G4: 581 | H4: 581 | I4: 581.75 | J4: 0 | K4: 0 | L4: 0 | M4: 0 | N4: 0 | O4: =SUM(D4-(E4+F4+G4+H4+I4+J4+K4+L4+M4+N4)) -> 0
A5: 45659 | B5: Fouzia Hafiz - 6 installments | C5: 6 weeks plan | D5: 3355 | E5: 2200 | F5: 200 | G5: 300 | H5: 300 | I5: 200 | J5: 100 | K5: 55 | L5: 0 | M5: 0 | N5: 0 | O5: =SUM(D5-(E5+F5+G5+H5+I5+J5+K5+L5+M5+N5)) -> 0
A6: 45700 | B6: Tahira Saleem - 4 installments | C6: 21 of every month | D6: 4670 | E6: 1250 | F6: 855 | G6: 0 | H6: 855 | I6: 1200 | J6: 510 | K6: 0 | L6: 0 | M6: 0 | N6: 0 | O6: =SUM(D6-(E6+F6+G6+H6+I6+J6+K6+L6+M6+N6)) -> 0
A7: 45771 | B7: Husnain - 6 installments | C7: first of every month | D7: 2725 | E7: 1250 | F7: 245.83 | G7: 245.83 | H7: 245.83 | I7: 245.83 | J7: 245.83 | K7: 245.83 | L7: 0 | M7: 0 | N7: 0 | O7: =SUM(D7-(E7+F7+G7+H7+I7+J7+K7+L7+M7+N7)) -> 0.02
A8: 45782 | B8: Shabab Shabir - 2 installmetns | C8: 7 of every month | D8: 1865 | E8: 700 | F8: 582.5 | G8: 582.5 | H8: 0 | I8: 0 | J8: 0 | K8: 0 | L8: 0 | M8: 0 | N8: 0 | O8: =SUM(D8-(E8+F8+G8+H8+I8+J8+K8+L8+M8+N8)) -> 0
A9: 45841 | B9: Sajid Hussain | D9: 4425 | E9: 1000 | F9: 1000 | G9: 825 | H9: 800 | I9: 800 | J9: 0 | K9: 0 | L9: 0 | M9: 0 | N9: 0 | O9: =SUM(D9-(E9+F9+G9+H9+I9+J9+K9+L9+M9+N9)) -> 0
A10: 45874 | B10: Nasir Ali | D10: 5100 | E10: 3000 | F10: 2100 | G10: 0 | H10: 0 | I10: 0 | J10: 0 | K10: 0 | L10: 0 | M10: 0 | N10: 0 | O10: =SUM(D10-(E10+F10+G10+H10+I10+J10+K10+L10+M10+N10)) -> 0
A11: 45972 | B11: Shakil Hussain | C11: 15/12/2025 | D11: 3300 | E11: 1650 | F11: 1650 | G11: 0 | H11: 0 | I11: 0 | J11: 0 | K11: 0 | L11: 0 | M11: 0 | N11: 0 | O11: =SUM(D11-(E11+F11+G11+H11+I11+J11+K11+L11+M11+N11)) -> 0
A12: 25/11/2025 | B12: Qasim Zaffar | C12: 25 of every month | D12: 9100 | E12: 4550 | F12: 2500 | G12: 2050 | H12: 0 | I12: 0 | J12: 0 | K12: 0 | L12: 0 | M12: 0 | N12: 0 | O12: =SUM(D12-(E12+F12+G12+H12+I12+J12+K12+L12+M12+N12)) -> 0
A13: 24/10/2025 | B13: Ghulam Nabi | D13: 4940 | E13: 1000 | F13: 1000 | G13: 0 | H13: 0 | I13: 0 | J13: 0 | K13: 0 | L13: 0 | M13: 0 | N13: 0 | O13: =SUM(D13-(E13+F13+G13+H13+I13+J13+K13+L13+M13+N13)) -> 2940
A14: 29/12/2025 | B14: Abdul Ghafoor | C14: 20 of every month | D14: 4200 | E14: 1200 | F14: 0 | G14: 0 | H14: 0 | I14: 0 | J14: 0 | K14: 0 | L14: 0 | M14: 0 | N14: 0 | O14: =SUM(D14-(E14+F14+G14+H14+I14+J14+K14+L14+M14+N14)) -> 3000
A15: 21/12/2025 | B15: Syed Abdul Waheed | C15: 46025 | D15: 6390 | E15: 3000 | F15: 2000 | G15: 1390 | H15: 0 | I15: 0 | J15: 0 | K15: 0 | L15: 0 | M15: 0 | N15: 0 | O15: =SUM(D15-(E15+F15+G15+H15+I15+J15+K15+L15+M15+N15)) -> 0
A16: 30/12/2025 | B16: Ahbida Bibi | C16: 4 weeks | D16: 2820 | E16: 1020 | F16: 0 | G16: 0 | H16: 0 | I16: 0 | J16: 0 | K16: 0 | L16: 0 | M16: 0 | N16: 0 | O16: =SUM(D16-(E16+F16+G16+H16+I16+J16+K16+L16+M16+N16)) -> 1800
D17: 0 | E17: 0 | F17: 0 | G17: 0 | H17: 0 | I17: 0 | J17: 0 | K17: 0 | L17: 0 | M17: 0 | N17: 0 | O17: =SUM(D17-(E17+F17+G17+H17+I17+J17+K17+L17+M17+N17)) -> 0
D18: 0 | E18: 0 | F18: 0 | G18: 0 | H18: 0 | I18: 0 | J18: 0 | K18: 0 | L18: 0 | M18: 0 | N18: 0 | O18: =SUM(D18-(E18+F18+G18+H18+I18+J18+K18+L18+M18+N18)) -> 0
D19: 0 | E19: 0 | F19: 0 | G19: 0 | H19: 0 | I19: 0 | J19: 0 | K19: 0 | L19: 0 | M19: 0 | N19: 0 | O19: =SUM(D19-(E19+F19+G19+H19+I19+J19+K19+L19+M19+N19)) -> 0
D20: 0 | E20: 0 | F20: 0 | G20: 0 | H20: 0 | I20: 0 | J20: 0 | K20: 0 | L20: 0 | M20: 0 | N20: 0 | O20: =SUM(D20-(E20+F20+G20+H20+I20+J20+K20+L20+M20+N20)) -> 0
D21: 0 | E21: 0 | F21: 0 | G21: 0 | H21: 0 | I21: 0 | J21: 0 | K21: 0 | L21: 0 | M21: 0 | N21: 0 | O21: =SUM(D21-(E21+F21+G21+H21+I21+J21+K21+L21+M21+N21)) -> 0
D22: 0 | E22: 0 | F22: 0 | G22: 0 | H22: 0 | I22: 0 | J22: 0 | K22: 0 | L22: 0 | M22: 0 | N22: 0 | O22: =SUM(D22-(E22+F22+G22+H22+I22+J22+K22+L22+M22+N22)) -> 0
D23: 0 | E23: 0 | F23: 0 | G23: 0 | H23: 0 | I23: 0 | J23: 0 | K23: 0 | L23: 0 | M23: 0 | N23: 0 | O23: =SUM(D23-(E23+F23+G23+H23+I23+J23+K23+L23+M23+N23)) -> 0
D24: 0 | E24: 0 | F24: 0 | G24: 0 | H24: 0 | I24: 0 | J24: 0 | K24: 0 | L24: 0 | M24: 0 | N24: 0 | O24: =SUM(D24-(E24+F24+G24+H24+I24+J24+K24+L24+M24+N24)) -> 0
D25: 0 | E25: 0 | F25: 0 | G25: 0 | H25: 0 | I25: 0 | J25: 0 | K25: 0 | L25: 0 | M25: 0 | N25: 0 | O25: =SUM(D25-(E25+F25+G25+H25+I25+J25+K25+L25+M25+N25)) -> 0
D26: 0 | E26: 0 | F26: 0 | G26: 0 | H26: 0 | I26: 0 | J26: 0 | K26: 0 | L26: 0 | M26: 0 | N26: 0 | O26: =SUM(D26-(E26+F26+G26+H26+I26+J26+K26+L26+M26+N26)) -> 0
D27: 0 | E27: 0 | F27: 0 | G27: 0 | H27: 0 | I27: 0 | J27: 0 | K27: 0 | L27: 0 | M27: 0 | N27: 0 | O27: =SUM(D27-(E27+F27+G27+H27+I27+J27+K27+L27+M27+N27)) -> 0
D28: 0 | E28: 0 | F28: 0 | G28: 0 | H28: 0 | I28: 0 | J28: 0 | K28: 0 | L28: 0 | M28: 0 | N28: 0 | O28: =SUM(D28-(E28+F28+G28+H28+I28+J28+K28+L28+M28+N28)) -> 0
... D30: 0 | E30: 0 | F30: 0 | G30: 0 | H30: 0 | I30: 0 | J30: 0 | K30: 0 | L30: 0 | M30: 0 | N30: 0 | O30: =SUM(D30-(E30+F30+G30+H30+I30+J30+K30+L30+M30+N30)) -> 0
C31: TOTAL | D31: =SUM(D4:D30) -> 56215 | O31: =SUM(O4:O30) -> 7740.02
A34: TRACK YOUR OTHER PAYMENTS HERE
A36: Date | B36: Name | C36: Total Amount Due | D36: Paid | E36: Balance
A37: 21/02/2023 | B37: Muhammad Saleem | C37: =644+120+40+70 -> 874 | D37: 0 | E37: =SUM(C37-D37) -> 874 | F37: MT
A38: 45658 | B38: WAJID ALI SHAH | C38: 340 | D38: 0 | E38: =SUM(C38-D38) -> 340
B39: RASHDA JABEEN | C39: 150 | D39: 0 | E39: =SUM(C39-D39) -> 150
B40: BASHARAT UMER | C40: 295 | D40: 0 | E40: =SUM(C40-D40) -> 295
B41: BAHAWAL Mother | C41: 35 | D41: 0 | E41: =SUM(C41-D41) -> 35
A42: 29/12/2025 | B42: Sajjad Ahmed | C42: 395 | D42: 0 | E42: =SUM(C42-D42) -> 395
A43: 45726 | B43: sohail khalil | C43: 2290 | D43: 0 | E43: =SUM(C43-D43) -> 2290 | F43: MT
A44: 45942 | B44: Rayan - Palestine | C44: 125 | D44: 125 | E44: =SUM(C44-D44) -> 0
A45: 31/12/2025 | B45: Syed Hamzah Ali Bukhari | C45: 5650 | D45: =3000+1600 -> 4600 | E45: =SUM(C45-D45) -> 1050
...

Sheet Vouchers
A1: NAME | B1: PNR | C1: AIRLINE | D1: TICKET ISSUED | E1: VOUCHER ISSUED | F1: Expiry Date | G1: STATUS | H1: VALUE | I1: NUMBER
A2: ARSHID/MOHAMMED MR | B2: AAOHCH | C2: SV | D2: 45541 | E2: 45586 | F2: 45897 | G2: REFUNDED | H2: DOF+NOSHOW+AD | I2: 07984745944
A3: HUSSAIN/MOHAMMAD AZAM MR | B3: CODBOH | C3: SV | D3: 45497 | E3: 45636 | F3: 45833 | G3: EXPIRED | H3: NAN | I3: 07814660314
